<?xml version="1.0"?>
<robot xmlns:xacro="http://www.ros.org/wiki/xacro">

  <!-- ===== Dimensions ===== -->
  <xacro:property name="wheel_radius"   value="0.05"/>
  <xacro:property name="wheel_width"    value="0.04"/>
  <xacro:property name="wheel_offset_y" value="0.18"/>
  <xacro:property name="caster_radius"  value="0.025"/>
  <xacro:property name="chassis_x"      value="0.30"/>
  <xacro:property name="chassis_y"      value="0.30"/>
  <xacro:property name="chassis_z"      value="0.15"/>

  <material name="white"><color rgba="1 1 1 1"/></material>
  <material name="black"><color rgba="0 0 0 1"/></material>

  <!-- ===== Frames ===== -->
  <link name="base_footprint"/>
  <link name="base_link"/>
  <joint name="base_joint" type="fixed">
    <parent link="base_footprint"/>
    <child link="base_link"/>
    <origin xyz="0 0 ${wheel_radius}"/>
  </joint>

  <!-- ===== Chassis ===== -->
  <joint name="chassis_joint" type="fixed">
    <parent link="base_link"/>
    <child link="chassis"/>
    <origin xyz="0 0 ${chassis_z/2}"/>
  </joint>
  <link name="chassis">
    <visual>
      <geometry><box size="${chassis_x} ${chassis_y} ${chassis_z}"/></geometry>
      <material name="white"/>
    </visual>
    <collision>
      <geometry><box size="${chassis_x} ${chassis_y} ${chassis_z}"/></geometry>
    </collision>
    <xacro:inertial_box mass="0.5" x="${chassis_x}" y="${chassis_y}" z="${chassis_z}">
      <origin xyz="0 0 0"/>
    </xacro:inertial_box>
  </link>

  <!-- ===== Drive wheels ===== -->
  <joint name="left_wheel_joint" type="continuous">
    <parent link="base_link"/>
    <child link="left_wheel"/>
    <origin xyz="0 ${wheel_offset_y} 0" rpy="-${pi/2} 0 0"/>
    <axis xyz="0 0 1"/>
  </joint>
  <link name="left_wheel">
    <visual>
      <geometry><cylinder radius="${wheel_radius}" length="${wheel_width}"/></geometry>
      <material name="black"/>
    </visual>
    <collision>
      <geometry><cylinder radius="${wheel_radius}" length="${wheel_width}"/></geometry>
    </collision>
    <xacro:inertial_cylinder mass="0.1" length="${wheel_width}" radius="${wheel_radius}">
      <origin xyz="0 0 0"/>
    </xacro:inertial_cylinder>
  </link>

  <joint name="right_wheel_joint" type="continuous">
    <parent link="base_link"/>
    <child link="right_wheel"/>
    <origin xyz="0 -${wheel_offset_y} 0" rpy="${pi/2} 0 0"/>
    <axis xyz="0 0 -1"/>
  </joint>
  <link name="right_wheel">
    <visual>
      <geometry><cylinder radius="${wheel_radius}" length="${wheel_width}"/></geometry>
      <material name="black"/>
    </visual>
    <collision>
      <geometry><cylinder radius="${wheel_radius}" length="${wheel_width}"/></geometry>
    </collision>
    <xacro:inertial_cylinder mass="0.1" length="${wheel_width}" radius="${wheel_radius}">
      <origin xyz="0 0 0"/>
    </xacro:inertial_cylinder>
  </link>

  <!-- ===== Casters (front + rear) ===== -->
  <joint name="caster_joint" type="fixed">
    <parent link="base_link"/>
    <child link="caster_wheel"/>
    <origin xyz="0.12 0 ${caster_radius - wheel_radius}"/>
  </joint>
  <link name="caster_wheel">
    <visual>
      <geometry><sphere radius="${caster_radius}"/></geometry>
      <material name="black"/>
    </visual>
    <collision>
      <geometry><sphere radius="${caster_radius}"/></geometry>
    </collision>
    <xacro:inertial_sphere mass="0.05" radius="${caster_radius}">
      <origin xyz="0 0 0"/>
    </xacro:inertial_sphere>
  </link>

  <joint name="caster_back_joint" type="fixed">
    <parent link="base_link"/>
    <child link="caster_back_wheel"/>
    <origin xyz="-0.12 0 ${caster_radius - wheel_radius}"/>
  </joint>
  <link name="caster_back_wheel">
    <visual>
      <geometry><sphere radius="${caster_radius}"/></geometry>
      <material name="black"/>
    </visual>
    <collision>
      <geometry><sphere radius="${caster_radius}"/></geometry>
    </collision>
    <xacro:inertial_sphere mass="0.05" radius="${caster_radius}">
      <origin xyz="0 0 0"/>
    </xacro:inertial_sphere>
  </link>

</robot>